Workbook

Sheet Table_1
A1: OrderID | B1: Date | C1: Region | D1: Seller | E1: Product | F1: Category | G1: Units | H1: UnitPrice | I1: Revenue | J1: Approved
A2: ORD-1181 | B2: 45495 | C2: North | D2: Bruno | E2: Gadget B | F2: Standard | G2: 1 | I2: =G2*H2
A3: ORD-1015 | B3: 45496 | C3: West | D3: Ana | E3: Widget B | F3: Discount | G3: 6 | H3: 105.9 | I3: =G3*H3
A4: ORD-1190 | B4: 45338 | C4: North | D4: Daniela | E4: Gadget B | F4: Premium | H4: 104.58 | I4: =G4*H4 | J4: FALSE
A5: ORD-1077 | B5: 45652 | C5: West | D5: Carlos | E5: Widget C | F5: Standard | G5: 12 | H5: 8.52 | I5: =G5*H5
A6: ORD-1181 | B6: 45502 | C6: North | D6: Carlos | E6: Gadget A | F6: Discount | H6: 102.59 | I6: =G6*H6 | J6: TRUE
A7: ORD-1192 | B7: 45368 | C7: Central | D7: Daniela | E7: Widget B | F7: Standard | G7: 13 | I7: =G7*H7 | J7: FALSE
A8: ORD-1023 | B8: 45312 | C8: Central | D8: Ana | E8: Widget C | F8: Discount | H8: 24.66 | I8: =G8*H8 | J8: FALSE
A9: ORD-1044 | B9: 45640 | C9: East | D9: Daniela | E9: Gadget B | F9: Standard | G9: 2 | H9: 78.69 | I9: =G9*H9 | J9: FALSE
A10: ORD-1054 | B10: 45363 | C10: East | D10: Bruno | E10: Gadget B | F10: Standard | G10: 11 | I10: =G10*H10 | J10: FALSE
A11: ORD-1013 | B11: 45382 | C11: West | D11: Ana | E11: Widget A | F11: Premium | I11: =G11*H11 | J11: FALSE
A12: ORD-1178 | B12: 45395 | C12: Central | D12: Fernanda | E12: Widget C | F12: Discount | G12: 11 | H12: 13.54 | I12: =G12*H12 | J12: TRUE
A13: ORD-1086 | B13: 45361 | C13: North | D13: Eduardo | E13: Gadget B | F13: Standard | G13: 5 | H13: 30.84 | I13: =G13*H13 | J13: FALSE
A14: ORD-1178 | B14: 45376 | C14: East | D14: Eduardo | E14: Widget A | F14: Standard | I14: =G14*H14 | J14: FALSE
A15: ORD-1170 | B15: 45299 | C15: Central | D15: Bruno | E15: Widget A | F15: Standard | I15: =G15*H15 | J15: FALSE
A16: ORD-1135 | B16: 45374 | C16: South | D16: Fernanda | E16: Gadget A | F16: Discount | I16: =G16*H16 | J16: TRUE
A17: ORD-1077 | B17: 45614 | C17: West | D17: Fernanda | E17: Widget B | F17: Standard | G17: 15 | H17: 51.63 | I17: =G17*H17
A18: ORD-1169 | B18: 45388 | C18: East | D18: Carlos | E18: Widget B | F18: Premium | H18: 105.83 | I18: =G18*H18 | J18: TRUE
A19: ORD-1090 | B19: 45322 | C19: West | D19: Eduardo | E19: Gadget A | F19: Discount | H19: 80.24 | I19: =G19*H19
A20: ORD-1057 | B20: 45583 | C20: East | D20: Carlos | E20: Gadget A | F20: Discount | G20: 4 | I20: =G20*H20 | J20: TRUE
A21: ORD-1054 | B21: 45394 | C21: North | D21: Fernanda | E21: Gadget A | F21: Premium | H21: 32.04 | I21: =G21*H21 | J21: TRUE
A22: ORD-1059 | B22: 45300 | C22: North | D22: Carlos | E22: Gadget A | F22: Standard | G22: 15 | I22: =G22*H22
A23: ORD-1017 | B23: 45592 | C23: West | D23: Daniela | E23: Gadget B | F23: Premium | H23: 51.45 | I23: =G23*H23 | J23: FALSE
A24: ORD-1061 | B24: 45357 | C24: West | D24: Bruno | E24: Gadget A | F24: Premium | H24: 70.9 | I24: =G24*H24 | J24: FALSE
A25: ORD-1039 | B25: 45382 | C25: Central | D25: Carlos | E25: Widget A | F25: Premium | H25: 26.92 | I25: =G25*H25 | J25: TRUE
A26: ORD-1004 | B26: 45328 | C26: West | D26: Eduardo | E26: Widget B | F26: Standard | H26: 81.11 | I26: =G26*H26 | J26: FALSE
A27: ORD-1127 | B27: 45497 | C27: Central | D27: Carlos | E27: Widget C | F27: Discount | H27: 19.21 | I27: =G27*H27
A28: ORD-1182 | B28: 45592 | C28: South | D28: Eduardo | E28: Widget A | F28: Standard | G28: 15 | H28: 116.61 | I28: =G28*H28 | J28: FALSE
A29: ORD-1074 | B29: 45294 | C29: North | D29: Fernanda | E29: Widget C | F29: Premium | H29: 12.83 | I29: =G29*H29
A30: ORD-1069 | B30: 45488 | C30: East | D30: Eduardo | E30: Widget B | F30: Premium | I30: =G30*H30
A31: ORD-1155 | B31: 45382 | C31: West | D31: Fernanda | E31: Widget C | F31: Discount | I31: =G31*H31 | J31: TRUE
A32: ORD-1007 | B32: 45527 | C32: East | D32: Ana | E32: Widget A | F32: Discount | G32: 15 | I32: =G32*H32 | J32: FALSE
A33: ORD-1099 | B33: 45587 | C33: North | D33: Fernanda | E33: Gadget A | F33: Discount | H33: 84.85 | I33: =G33*H33 | J33: TRUE
A34: ORD-1121 | B34: 45605 | C34: South | D34: Bruno | E34: Widget C | F34: Discount | H34: 30.97 | I34: =G34*H34
A35: ORD-1030 | B35: 45338 | C35: Central | D35: Ana | E35: Gadget A | F35: Discount | I35: =G35*H35 | J35: FALSE
A36: ORD-1141 | B36: 45306 | C36: Central | D36: Eduardo | E36: Widget A | F36: Standard | H36: 42.25 | I36: =G36*H36
A37: ORD-1034 | B37: 45502 | C37: East | D37: Bruno | E37: Widget A | F37: Premium | G37: 10 | I37: =G37*H37 | J37: TRUE
A38: ORD-1100 | B38: 45513 | C38: East | D38: Carlos | E38: Widget B | F38: Standard | I38: =G38*H38 | J38: TRUE
A39: ORD-1068 | B39: 45536 | C39: South | D39: Daniela | E39: Gadget A | F39: Discount | G39: 15 | I39: =G39*H39 | J39: FALSE
A40: ORD-1117 | B40: 45410 | C40: South | D40: Carlos | E40: Widget A | F40: Standard | H40: 94.27 | I40: =G40*H40
...

Sheet Table_2
A1: OrderID | B1: Date | C1: Region | D1: Seller | E1: Product | F1: Category | G1: Units | H1: UnitPrice | I1: Revenue | J1: Approved
A2: ORD-1171 | B2: 45614 | C2: South | D2: Fernanda | E2: Widget C | F2: Standard | H2: 60.53 | I2: =G2*H2
A3: ORD-1019 | B3: 45525 | C3: Central | D3: Daniela | E3: Widget C | F3: Discount | G3: 4 | I3: =G3*H3 | J3: TRUE
A4: ORD-1036 | B4: 45438 | C4: Central | D4: Eduardo | E4: Gadget B | F4: Discount | H4: 90.03 | I4: =G4*H4 | J4: FALSE
A5: ORD-1029 | B5: 45464 | C5: West | D5: Ana | E5: Widget C | F5: Standard | G5: 1 | I5: =G5*H5 | J5: TRUE
A6: ORD-1173 | B6: 45402 | C6: Central | D6: Bruno | E6: Gadget A | F6: Discount | H6: 38.45 | I6: =G6*H6 | J6: TRUE
A7: ORD-1098 | B7: 45432 | C7: Central | D7: Eduardo | E7: Gadget B | F7: Standard | G7: 9 | I7: =G7*H7 | J7: FALSE
A8: ORD-1020 | B8: 45607 | C8: Central | D8: Eduardo | E8: Gadget B | F8: Premium | G8: 13 | H8: 86.4 | I8: =G8*H8
A9: ORD-1015 | B9: 45621 | C9: South | D9: Eduardo | E9: Widget A | F9: Discount | H9: 28.01 | I9: =G9*H9
A10: ORD-1180 | B10: 45522 | C10: Central | D10: Daniela | E10: Gadget A | F10: Standard | G10: 2 | I10: =G10*H10
A11: ORD-1176 | B11: 45508 | C11: North | D11: Eduardo | E11: Widget C | F11: Standard | I11: =G11*H11 | J11: FALSE
A12: ORD-1039 | B12: 45358 | C12: South | D12: Carlos | E12: Widget B | F12: Premium | H12: 63.64 | I12: =G12*H12
A13: ORD-1078 | B13: 45359 | C13: South | D13: Carlos | E13: Widget A | F13: Discount | I13: =G13*H13 | J13: TRUE
A14: ORD-1060 | B14: 45407 | C14: Central | D14: Carlos | E14: Gadget A | F14: Standard | G14: 12 | H14: 113.48 | I14: =G14*H14 | J14: FALSE
A15: ORD-1043 | B15: 45542 | C15: Central | D15: Eduardo | E15: Widget A | F15: Discount | G15: 6 | H15: 116.3 | I15: =G15*H15 | J15: TRUE
A16: ORD-1182 | B16: 45546 | C16: West | D16: Eduardo | E16: Widget C | F16: Premium | G16: 6 | H16: 103.2 | I16: =G16*H16 | J16: FALSE
A17: ORD-1027 | B17: 45595 | C17: East | D17: Daniela | E17: Widget C | F17: Discount | G17: 14 | H17: 101.27 | I17: =G17*H17 | J17: FALSE
A18: ORD-1063 | B18: 45369 | C18: East | D18: Bruno | E18: Widget B | F18: Standard | G18: 15 | H18: 79.51 | I18: =G18*H18
A19: ORD-1139 | B19: 45465 | C19: East | D19: Carlos | E19: Gadget B | F19: Premium | G19: 7 | I19: =G19*H19
A20: ORD-1043 | B20: 45580 | C20: West | D20: Eduardo | E20: Gadget A | F20: Premium | I20: =G20*H20 | J20: FALSE
A21: ORD-1146 | B21: 45522 | C21: West | D21: Carlos | E21: Gadget A | F21: Premium | I21: =G21*H21 | J21: FALSE
A22: ORD-1192 | B22: 45576 | C22: Central | D22: Eduardo | E22: Widget A | F22: Premium | G22: 7 | I22: =G22*H22 | J22: TRUE
A23: ORD-1198 | B23: 45528 | C23: East | D23: Carlos | E23: Widget A | F23: Discount | G23: 13 | H23: 18.54 | I23: =G23*H23 | J23: FALSE
A24: ORD-1113 | B24: 45555 | C24: West | D24: Eduardo | E24: Gadget A | F24: Standard | I24: =G24*H24 | J24: TRUE
A25: ORD-1071 | B25: 45379 | C25: South | D25: Eduardo | E25: Widget A | F25: Discount | G25: 14 | H25: 67.82 | I25: =G25*H25
A26: ORD-1055 | B26: 45420 | C26: Central | D26: Bruno | E26: Widget C | F26: Premium | H26: 101.73 | I26: =G26*H26
A27: ORD-1030 | B27: 45608 | C27: North | D27: Eduardo | E27: Widget C | F27: Premium | H27: 35.75 | I27: =G27*H27 | J27: FALSE
A28: ORD-1048 | B28: 45445 | C28: Central | D28: Eduardo | E28: Gadget B | F28: Standard | G28: 6 | H28: 70.55 | I28: =G28*H28 | J28: TRUE
A29: ORD-1019 | B29: 45573 | C29: West | D29: Ana | E29: Widget A | F29: Standard | G29: 11 | H29: 99.4 | I29: =G29*H29 | J29: FALSE
A30: ORD-1144 | B30: 45304 | C30: South | D30: Eduardo | E30: Gadget B | F30: Premium | I30: =G30*H30 | J30: TRUE
A31: ORD-1156 | B31: 45384 | C31: East | D31: Carlos | E31: Widget A | F31: Premium | H31: 46.9 | I31: =G31*H31 | J31: TRUE
A32: ORD-1199 | B32: 45618 | C32: South | D32: Ana | E32: Widget B | F32: Discount | G32: 2 | H32: 29.3 | I32: =G32*H32
A33: ORD-1014 | B33: 45371 | C33: Central | D33: Daniela | E33: Widget B | F33: Premium | I33: =G33*H33 | J33: FALSE
A34: ORD-1174 | B34: 45299 | C34: Central | D34: Bruno | E34: Widget B | F34: Discount | I34: =G34*H34
A35: ORD-1129 | B35: 45540 | C35: North | D35: Daniela | E35: Gadget B | F35: Premium | G35: 9 | H35: 85.46 | I35: =G35*H35
A36: ORD-1175 | B36: 45338 | C36: South | D36: Ana | E36: Widget B | F36: Premium | G36: 3 | I36: =G36*H36
A37: ORD-1086 | B37: 45623 | C37: West | D37: Carlos | E37: Widget B | F37: Standard | I37: =G37*H37
A38: ORD-1105 | B38: 45315 | C38: South | D38: Fernanda | E38: Gadget B | F38: Discount | G38: 11 | H38: 65.52 | I38: =G38*H38 | J38: TRUE
A39: ORD-1127 | B39: 45392 | C39: North | D39: Eduardo | E39: Gadget A | F39: Discount | G39: 1 | I39: =G39*H39
A40: ORD-1104 | B40: 45372 | C40: Central | D40: Ana | E40: Gadget A | F40: Standard | I40: =G40*H40 | J40: FALSE
...

Sheet Table_3
A1: OrderID | B1: Date | C1: Region | D1: Seller | E1: Product | F1: Category | G1: Units | H1: UnitPrice | I1: Revenue | J1: Approved
A2: ORD-1017 | B2: 45391 | C2: Central | D2: Carlos | E2: Widget B | F2: Discount | G2: 12 | H2: 32.65 | I2: =G2*H2
A3: ORD-1192 | B3: 45318 | C3: North | D3: Bruno | E3: Widget B | F3: Discount | G3: 11 | H3: 83.96 | I3: =G3*H3 | J3: TRUE
A4: ORD-1015 | B4: 45353 | C4: South | D4: Bruno | E4: Widget B | F4: Premium | I4: =G4*H4
A5: ORD-1018 | B5: 45450 | C5: North | D5: Fernanda | E5: Widget A | F5: Discount | G5: 8 | H5: 88.39 | I5: =G5*H5
A6: ORD-1078 | B6: 45416 | C6: South | D6: Ana | E6: Gadget A | F6: Standard | I6: =G6*H6
A7: ORD-1023 | B7: 45296 | C7: East | D7: Daniela | E7: Widget C | F7: Standard | H7: 43.45 | I7: =G7*H7 | J7: TRUE
A8: ORD-1171 | B8: 45384 | C8: South | D8: Bruno | E8: Gadget A | F8: Discount | H8: 90.49 | I8: =G8*H8 | J8: TRUE
A9: ORD-1036 | B9: 45576 | C9: West | D9: Bruno | E9: Gadget B | F9: Discount | G9: 4 | I9: =G9*H9
A10: ORD-1116 | B10: 45486 | C10: West | D10: Bruno | E10: Widget A | F10: Standard | G10: 11 | H10: 97.32 | I10: =G10*H10
A11: ORD-1186 | B11: 45474 | C11: South | D11: Ana | E11: Widget B | F11: Discount | G11: 15 | I11: =G11*H11 | J11: FALSE
A12: ORD-1127 | B12: 45394 | C12: East | D12: Carlos | E12: Widget A | F12: Premium | G12: 7 | I12: =G12*H12
A13: ORD-1127 | B13: 45556 | C13: East | D13: Daniela | E13: Gadget A | F13: Standard | I13: =G13*H13 | J13: TRUE
A14: ORD-1068 | B14: 45358 | C14: West | D14: Carlos | E14: Widget A | F14: Discount | H14: 65.72 | I14: =G14*H14
A15: ORD-1103 | B15: 45504 | C15: South | D15: Daniela | E15: Widget B | F15: Premium | G15: 3 | I15: =G15*H15 | J15: FALSE
A16: ORD-1102 | B16: 45531 | C16: North | D16: Eduardo | E16: Gadget A | F16: Premium | I16: =G16*H16 | J16: FALSE
A17: ORD-1057 | B17: 45508 | C17: North | D17: Daniela | E17: Gadget A | F17: Standard | I17: =G17*H17
A18: ORD-1061 | B18: 45473 | C18: North | D18: Ana | E18: Gadget B | F18: Premium | I18: =G18*H18
A19: ORD-1130 | B19: 45526 | C19: West | D19: Bruno | E19: Gadget A | F19: Discount | H19: 98.31 | I19: =G19*H19 | J19: FALSE
A20: ORD-1007 | B20: 45320 | C20: Central | D20: Daniela | E20: Gadget B | F20: Premium | G20: 4 | I20: =G20*H20 | J20: TRUE
A21: ORD-1200 | B21: 45386 | C21: West | D21: Ana | E21: Widget C | F21: Premium | H21: 17.49 | I21: =G21*H21
A22: ORD-1021 | B22: 45522 | C22: West | D22: Eduardo | E22: Gadget B | F22: Discount | G22: 13 | I22: =G22*H22 | J22: TRUE
A23: ORD-1041 | B23: 45622 | C23: East | D23: Bruno | E23: Widget A | F23: Premium | G23: 8 | H23: 50.22 | I23: =G23*H23
A24: ORD-1041 | B24: 45389 | C24: South | D24: Eduardo | E24: Widget A | F24: Premium | H24: 55.63 | I24: =G24*H24 | J24: FALSE
A25: ORD-1146 | B25: 45418 | C25: East | D25: Ana | E25: Widget B | F25: Premium | G25: 2 | I25: =G25*H25 | J25: TRUE
A26: ORD-1023 | B26: 45478 | C26: South | D26: Fernanda | E26: Widget A | F26: Discount | H26: 107.05 | I26: =G26*H26 | J26: FALSE
A27: ORD-1196 | B27: 45353 | C27: North | D27: Fernanda | E27: Gadget B | F27: Standard | G27: 1 | H27: 60.74 | I27: =G27*H27 | J27: FALSE
A28: ORD-1084 | B28: 45603 | C28: Central | D28: Eduardo | E28: Widget B | F28: Standard | H28: 69.2 | I28: =G28*H28
A29: ORD-1019 | B29: 45636 | C29: South | D29: Eduardo | E29: Gadget B | F29: Premium | G29: 5 | I29: =G29*H29 | J29: TRUE
A30: ORD-1156 | B30: 45594 | C30: South | D30: Bruno | E30: Widget A | F30: Premium | H30: 17.86 | I30: =G30*H30
A31: ORD-1003 | B31: 45324 | C31: West | D31: Bruno | E31: Widget B | F31: Premium | H31: 116.57 | I31: =G31*H31 | J31: FALSE
A32: ORD-1035 | B32: 45296 | C32: North | D32: Carlos | E32: Gadget B | F32: Standard | G32: 11 | I32: =G32*H32 | J32: TRUE
A33: ORD-1052 | B33: 45333 | C33: Central | D33: Bruno | E33: Widget B | F33: Standard | H33: 85.39 | I33: =G33*H33
A34: ORD-1010 | B34: 45509 | C34: East | D34: Carlos | E34: Gadget A | F34: Premium | H34: 46.95 | I34: =G34*H34 | J34: FALSE
A35: ORD-1129 | B35: 45603 | C35: South | D35: Bruno | E35: Gadget A | F35: Discount | I35: =G35*H35 | J35: TRUE
A36: ORD-1185 | B36: 45645 | C36: Central | D36: Bruno | E36: Widget A | F36: Discount | H36: 59.07 | I36: =G36*H36 | J36: FALSE
A37: ORD-1073 | B37: 45489 | C37: Central | D37: Bruno | E37: Gadget A | F37: Discount | G37: 1 | H37: 48.85 | I37: =G37*H37 | J37: FALSE
A38: ORD-1123 | B38: 45625 | C38: South | D38: Fernanda | E38: Widget C | F38: Premium | I38: =G38*H38
A39: ORD-1007 | B39: 45498 | C39: Central | D39: Daniela | E39: Gadget B | F39: Standard | G39: 13 | I39: =G39*H39 | J39: FALSE
A40: ORD-1150 | B40: 45366 | C40: Central | D40: Bruno | E40: Widget A | F40: Premium | G40: 2 | H40: 58.66 | I40: =G40*H40 | J40: TRUE
...

Sheet Table_4
A1: OrderID | B1: Date | C1: Region | D1: Seller | E1: Product | F1: Category | G1: Units | H1: UnitPrice | I1: Revenue | J1: Approved
A2: ORD-1076 | B2: 45518 | C2: North | D2: Carlos | E2: Widget B | F2: Standard | I2: =G2*H2
A3: ORD-1019 | B3: 45648 | C3: South | D3: Carlos | E3: Widget A | F3: Standard | H3: 85.08 | I3: =G3*H3 | J3: FALSE
A4: ORD-1175 | B4: 45536 | C4: West | D4: Eduardo | E4: Widget B | F4: Premium | G4: 4 | H4: 42.12 | I4: =G4*H4
A5: ORD-1062 | B5: 45510 | C5: South | D5: Bruno | E5: Widget B | F5: Premium | G5: 14 | I5: =G5*H5 | J5: TRUE
A6: ORD-1099 | B6: 45454 | C6: West | D6: Fernanda | E6: Widget B | F6: Discount | H6: 36.5 | I6: =G6*H6
A7: ORD-1092 | B7: 45363 | C7: North | D7: Bruno | E7: Widget B | F7: Premium | I7: =G7*H7 | J7: FALSE
A8: ORD-1099 | B8: 45340 | C8: East | D8: Bruno | E8: Widget A | F8: Standard | G8: 5 | H8: 93.96 | I8: =G8*H8 | J8: FALSE
A9: ORD-1014 | B9: 45455 | C9: South | D9: Bruno | E9: Widget A | F9: Premium | I9: =G9*H9 | J9: TRUE
A10: ORD-1131 | B10: 45430 | C10: East | D10: Daniela | E10: Widget C | F10: Premium | G10: 11 | I10: =G10*H10
A11: ORD-1195 | B11: 45445 | C11: Central | D11: Fernanda | E11: Widget C | F11: Standard | G11: 2 | I11: =G11*H11 | J11: FALSE
A12: ORD-1086 | B12: 45293 | C12: West | D12: Ana | E12: Gadget B | F12: Discount | H12: 86.81 | I12: =G12*H12
A13: ORD-1102 | B13: 45419 | C13: Central | D13: Fernanda | E13: Widget A | F13: Premium | I13: =G13*H13 | J13: TRUE
A14: ORD-1014 | B14: 45591 | C14: South | D14: Ana | E14: Gadget A | F14: Standard | G14: 10 | H14: 59.55 | I14: =G14*H14 | J14: FALSE
A15: ORD-1031 | B15: 45530 | C15: North | D15: Bruno | E15: Widget B | F15: Premium | G15: 10 | H15: 107.09 | I15: =G15*H15 | J15: FALSE
A16: ORD-1077 | B16: 45558 | C16: East | D16: Carlos | E16: Gadget A | F16: Standard | G16: 10 | I16: =G16*H16 | J16: TRUE
A17: ORD-1040 | B17: 45398 | C17: East | D17: Fernanda | E17: Widget C | F17: Standard | G17: 14 | I17: =G17*H17 | J17: FALSE
A18: ORD-1195 | B18: 45526 | C18: West | D18: Bruno | E18: Gadget B | F18: Standard | H18: 41.36 | I18: =G18*H18
A19: ORD-1053 | B19: 45475 | C19: West | D19: Carlos | E19: Widget C | F19: Premium | I19: =G19*H19
A20: ORD-1123 | B20: 45326 | C20: South | D20: Ana | E20: Widget A | F20: Premium | I20: =G20*H20
A21: ORD-1094 | B21: 45474 | C21: East | D21: Eduardo | E21: Widget C | F21: Discount | G21: 15 | I21: =G21*H21
A22: ORD-1002 | B22: 45539 | C22: North | D22: Daniela | E22: Widget C | F22: Standard | I22: =G22*H22 | J22: TRUE
A23: ORD-1111 | B23: 45563 | C23: Central | D23: Fernanda | E23: Widget B | F23: Premium | I23: =G23*H23 | J23: TRUE
A24: ORD-1028 | B24: 45417 | C24: West | D24: Fernanda | E24: Gadget B | F24: Discount | I24: =G24*H24
A25: ORD-1122 | B25: 45524 | C25: Central | D25: Fernanda | E25: Gadget B | F25: Standard | H25: 86.01 | I25: =G25*H25 | J25: TRUE
A26: ORD-1100 | B26: 45588 | C26: East | D26: Eduardo | E26: Gadget A | F26: Standard | G26: 14 | I26: =G26*H26
A27: ORD-1093 | B27: 45597 | C27: Central | D27: Ana | E27: Gadget A | F27: Discount | G27: 15 | H27: 67.31 | I27: =G27*H27 | J27: TRUE
A28: ORD-1018 | B28: 45583 | C28: South | D28: Bruno | E28: Widget B | F28: Premium | G28: 7 | H28: 108.29 | I28: =G28*H28 | J28: FALSE
A29: ORD-1009 | B29: 45367 | C29: Central | D29: Fernanda | E29: Widget A | F29: Standard | G29: 1 | I29: =G29*H29 | J29: TRUE
A30: ORD-1135 | B30: 45319 | C30: South | D30: Carlos | E30: Gadget A | F30: Standard | H30: 71.3 | I30: =G30*H30 | J30: TRUE
A31: ORD-1080 | B31: 45355 | C31: West | D31: Fernanda | E31: Widget C | F31: Discount | G31: 1 | H31: 37.9 | I31: =G31*H31 | J31: TRUE
A32: ORD-1139 | B32: 45390 | C32: South | D32: Carlos | E32: Widget C | F32: Standard | G32: 14 | H32: 104.72 | I32: =G32*H32 | J32: TRUE
A33: ORD-1189 | B33: 45484 | C33: West | D33: Ana | E33: Gadget B | F33: Standard | I33: =G33*H33 | J33: TRUE
A34: ORD-1180 | B34: 45370 | C34: Central | D34: Carlos | E34: Widget C | F34: Standard | G34: 9 | I34: =G34*H34
A35: ORD-1026 | B35: 45612 | C35: Central | D35: Eduardo | E35: Widget C | F35: Premium | H35: 109.12 | I35: =G35*H35 | J35: TRUE
A36: ORD-1174 | B36: 45305 | C36: South | D36: Daniela | E36: Gadget B | F36: Premium | G36: 6 | H36: 97.59 | I36: =G36*H36 | J36: FALSE
A37: ORD-1166 | B37: 45410 | C37: South | D37: Daniela | E37: Widget A | F37: Premium | H37: 52.81 | I37: =G37*H37
A38: ORD-1037 | B38: 45385 | C38: West | D38: Bruno | E38: Widget C | F38: Discount | G38: 14 | H38: 38.51 | I38: =G38*H38 | J38: TRUE
A39: ORD-1190 | B39: 45649 | C39: West | D39: Eduardo | E39: Gadget A | F39: Standard | G39: 9 | I39: =G39*H39
A40: ORD-1038 | B40: 45355 | C40: South | D40: Ana | E40: Gadget A | F40: Standard | I40: =G40*H40
...

Sheet Table_5
A1: OrderID | B1: Date | C1: Region | D1: Seller | E1: Product | F1: Category | G1: Units | H1: UnitPrice | I1: Revenue | J1: Approved
A2: ORD-1080 | B2: 45622 | C2: Central | D2: Fernanda | E2: Widget C | F2: Premium | G2: 10 | H2: 87.11 | I2: =G2*H2
A3: ORD-1155 | B3: 45589 | C3: North | D3: Bruno | E3: Widget C | F3: Premium | H3: 97.13 | I3: =G3*H3 | J3: FALSE
A4: ORD-1146 | B4: 45566 | C4: Central | D4: Ana | E4: Widget A | F4: Discount | G4: 10 | I4: =G4*H4
A5: ORD-1010 | B5: 45657 | C5: West | D5: Daniela | E5: Widget B | F5: Standard | I5: =G5*H5 | J5: TRUE
A6: ORD-1139 | B6: 45302 | C6: West | D6: Bruno | E6: Gadget A | F6: Standard | I6: =G6*H6
A7: ORD-1157 | B7: 45403 | C7: North | D7: Fernanda | E7: Widget C | F7: Premium | I7: =G7*H7 | J7: FALSE
A8: ORD-1140 | B8: 45350 | C8: South | D8: Carlos | E8: Gadget B | F8: Premium | H8: 88.34 | I8: =G8*H8
A9: ORD-1096 | B9: 45466 | C9: North | D9: Daniela | E9: Gadget A | F9: Premium | G9: 8 | H9: 10.85 | I9: =G9*H9 | J9: TRUE
A10: ORD-1102 | B10: 45298 | C10: West | D10: Carlos | E10: Gadget B | F10: Standard | G10: 8 | H10: 76.61 | I10: =G10*H10 | J10: FALSE
A11: ORD-1078 | B11: 45355 | C11: Central | D11: Bruno | E11: Widget A | F11: Premium | G11: 7 | H11: 102.42 | I11: =G11*H11
A12: ORD-1083 | B12: 45416 | C12: South | D12: Fernanda | E12: Widget A | F12: Premium | H12: 8.45 | I12: =G12*H12 | J12: FALSE
A13: ORD-1027 | B13: 45341 | C13: East | D13: Ana | E13: Gadget B | F13: Discount | I13: =G13*H13 | J13: TRUE
A14: ORD-1194 | B14: 45398 | C14: Central | D14: Eduardo | E14: Widget B | F14: Discount | G14: 8 | H14: 55.44 | I14: =G14*H14 | J14: TRUE
A15: ORD-1000 | B15: 45438 | C15: East | D15: Fernanda | E15: Gadget A | F15: Premium | G15: 15 | I15: =G15*H15 | J15: FALSE
A16: ORD-1167 | B16: 45403 | C16: West | D16: Eduardo | E16: Gadget B | F16: Premium | G16: 15 | I16: =G16*H16
A17: ORD-1103 | B17: 45644 | C17: South | D17: Ana | E17: Gadget B | F17: Standard | H17: 92.26 | I17: =G17*H17 | J17: FALSE
A18: ORD-1070 | B18: 45651 | C18: Central | D18: Fernanda | E18: Gadget B | F18: Discount | H18: 17.73 | I18: =G18*H18
A19: ORD-1105 | B19: 45335 | C19: South | D19: Bruno | E19: Widget C | F19: Discount | I19: =G19*H19 | J19: FALSE
A20: ORD-1155 | B20: 45325 | C20: Central | D20: Carlos | E20: Widget B | F20: Standard | G20: 15 | H20: 69.77 | I20: =G20*H20
A21: ORD-1100 | B21: 45475 | C21: Central | D21: Carlos | E21: Widget C | F21: Premium | G21: 9 | I21: =G21*H21 | J21: FALSE
A22: ORD-1083 | B22: 45360 | C22: West | D22: Daniela | E22: Gadget B | F22: Standard | I22: =G22*H22 | J22: FALSE
A23: ORD-1039 | B23: 45567 | C23: South | D23: Fernanda | E23: Widget A | F23: Standard | I23: =G23*H23 | J23: FALSE
A24: ORD-1173 | B24: 45378 | C24: North | D24: Eduardo | E24: Gadget B | F24: Discount | G24: 5 | H24: 92.94 | I24: =G24*H24
A25: ORD-1036 | B25: 45474 | C25: West | D25: Daniela | E25: Gadget B | F25: Discount | G25: 6 | H25: 72.14 | I25: =G25*H25
A26: ORD-1066 | B26: 45578 | C26: West | D26: Ana | E26: Gadget A | F26: Standard | G26: 14 | H26: 58.28 | I26: =G26*H26 | J26: FALSE
A27: ORD-1036 | B27: 45346 | C27: West | D27: Fernanda | E27: Gadget A | F27: Premium | H27: 87.78 | I27: =G27*H27 | J27: FALSE
A28: ORD-1065 | B28: 45560 | C28: East | D28: Carlos | E28: Gadget A | F28: Premium | G28: 2 | I28: =G28*H28 | J28: FALSE
A29: ORD-1114 | B29: 45487 | C29: North | D29: Bruno | E29: Gadget B | F29: Discount | G29: 14 | I29: =G29*H29
A30: ORD-1049 | B30: 45314 | C30: North | D30: Fernanda | E30: Widget C | F30: Standard | I30: =G30*H30
A31: ORD-1156 | B31: 45508 | C31: North | D31: Daniela | E31: Widget C | F31: Discount | G31: 13 | H31: 69.73 | I31: =G31*H31 | J31: FALSE
A32: ORD-1080 | B32: 45383 | C32: Central | D32: Ana | E32: Widget A | F32: Premium | G32: 6 | H32: 86.84 | I32: =G32*H32
A33: ORD-1172 | B33: 45568 | C33: North | D33: Ana | E33: Widget C | F33: Premium | I33: =G33*H33
A34: ORD-1096 | B34: 45391 | C34: South | D34: Eduardo | E34: Widget A | F34: Premium | H34: 18.58 | I34: =G34*H34 | J34: TRUE
A35: ORD-1032 | B35: 45310 | C35: East | D35: Ana | E35: Gadget B | F35: Premium | G35: 9 | I35: =G35*H35 | J35: TRUE
A36: ORD-1020 | B36: 45470 | C36: West | D36: Fernanda | E36: Widget C | F36: Standard | G36: 6 | H36: 52.93 | I36: =G36*H36 | J36: FALSE
A37: ORD-1123 | B37: 45564 | C37: West | D37: Ana | E37: Gadget A | F37: Standard | H37: 7.39 | I37: =G37*H37
A38: ORD-1152 | B38: 45461 | C38: Central | D38: Daniela | E38: Widget B | F38: Discount | I38: =G38*H38
A39: ORD-1187 | B39: 45642 | C39: South | D39: Ana | E39: Widget A | F39: Premium | I39: =G39*H39 | J39: TRUE
A40: ORD-1157 | B40: 45324 | C40: North | D40: Eduardo | E40: Widget A | F40: Standard | H40: 83.54 | I40: =G40*H40 | J40: FALSE
...

Sheet Table_6
A1: OrderID | B1: Date | C1: Region | D1: Seller | E1: Product | F1: Category | G1: Units | H1: UnitPrice | I1: Revenue | J1: Approved
A2: ORD-1117 | B2: 45532 | C2: South | D2: Daniela | E2: Gadget A | F2: Standard | G2: 2 | H2: 15 | I2: =G2*H2 | J2: TRUE
A3: ORD-1100 | B3: 45445 | C3: East | D3: Bruno | E3: Widget A | F3: Premium | H3: 71.44 | I3: =G3*H3
A4: ORD-1026 | B4: 45536 | C4: South | D4: Fernanda | E4: Widget A | F4: Premium | G4: 4 | H4: 51.18 | I4: =G4*H4
A5: ORD-1010 | B5: 45368 | C5: North | D5: Carlos | E5: Gadget A | F5: Discount | H5: 42.56 | I5: =G5*H5
A6: ORD-1196 | B6: 45331 | C6: North | D6: Eduardo | E6: Gadget B | F6: Premium | G6: 4 | H6: 78.54 | I6: =G6*H6 | J6: TRUE
A7: ORD-1126 | B7: 45314 | C7: West | D7: Fernanda | E7: Widget B | F7: Standard | I7: =G7*H7
A8: ORD-1048 | B8: 45443 | C8: East | D8: Fernanda | E8: Widget A | F8: Standard | G8: 7 | I8: =G8*H8
A9: ORD-1094 | B9: 45412 | C9: West | D9: Ana | E9: Widget A | F9: Standard | I9: =G9*H9 | J9: FALSE
A10: ORD-1007 | B10: 45414 | C10: Central | D10: Daniela | E10: Gadget B | F10: Premium | I10: =G10*H10 | J10: FALSE
A11: ORD-1175 | B11: 45605 | C11: East | D11: Daniela | E11: Widget C | F11: Standard | H11: 32.43 | I11: =G11*H11 | J11: FALSE
A12: ORD-1026 | B12: 45433 | C12: West | D12: Ana | E12: Gadget B | F12: Discount | G12: 7 | I12: =G12*H12 | J12: FALSE
A13: ORD-1013 | B13: 45389 | C13: Central | D13: Eduardo | E13: Gadget A | F13: Premium | G13: 2 | I13: =G13*H13
A14: ORD-1152 | B14: 45383 | C14: West | D14: Carlos | E14: Widget C | F14: Discount | I14: =G14*H14 | J14: FALSE
A15: ORD-1038 | B15: 45295 | C15: North | D15: Eduardo | E15: Gadget A | F15: Standard | H15: 16.05 | I15: =G15*H15 | J15: FALSE
A16: ORD-1130 | B16: 45535 | C16: East | D16: Carlos | E16: Widget C | F16: Standard | G16: 13 | I16: =G16*H16 | J16: TRUE
A17: ORD-1075 | B17: 45555 | C17: Central | D17: Daniela | E17: Gadget B | F17: Standard | G17: 8 | I17: =G17*H17 | J17: FALSE
A18: ORD-1045 | B18: 45605 | C18: West | D18: Eduardo | E18: Gadget A | F18: Premium | G18: 14 | H18: 108.82 | I18: =G18*H18
A19: ORD-1045 | B19: 45327 | C19: North | D19: Carlos | E19: Gadget A | F19: Discount | H19: 78.02 | I19: =G19*H19 | J19: TRUE
A20: ORD-1098 | B20: 45550 | C20: North | D20: Carlos | E20: Widget C | F20: Standard | G20: 12 | H20: 100.06 | I20: =G20*H20 | J20: TRUE
A21: ORD-1142 | B21: 45635 | C21: Central | D21: Eduardo | E21: Widget A | F21: Premium | I21: =G21*H21
A22: ORD-1165 | B22: 45591 | C22: East | D22: Bruno | E22: Gadget A | F22: Discount | G22: 8 | H22: 14.58 | I22: =G22*H22
A23: ORD-1108 | B23: 45654 | C23: South | D23: Carlos | E23: Gadget B | F23: Discount | G23: 13 | I23: =G23*H23
A24: ORD-1002 | B24: 45569 | C24: West | D24: Carlos | E24: Widget B | F24: Standard | G24: 11 | I24: =G24*H24 | J24: TRUE
A25: ORD-1011 | B25: 45535 | C25: East | D25: Daniela | E25: Gadget A | F25: Standard | H25: 105.61 | I25: =G25*H25 | J25: TRUE
A26: ORD-1163 | B26: 45481 | C26: East | D26: Ana | E26: Widget C | F26: Standard | G26: 13 | H26: 18.49 | I26: =G26*H26 | J26: TRUE
A27: ORD-1119 | B27: 45480 | C27: East | D27: Fernanda | E27: Widget C | F27: Standard | G27: 1 | H27: 14.59 | I27: =G27*H27 | J27: TRUE
A28: ORD-1084 | B28: 45440 | C28: East | D28: Bruno | E28: Gadget A | F28: Standard | H28: 106.95 | I28: =G28*H28 | J28: FALSE
A29: ORD-1022 | B29: 45349 | C29: South | D29: Eduardo | E29: Gadget B | F29: Premium | I29: =G29*H29 | J29: TRUE
A30: ORD-1181 | B30: 45308 | C30: Central | D30: Bruno | E30: Gadget B | F30: Standard | G30: 1 | H30: 31.54 | I30: =G30*H30 | J30: FALSE
A31: ORD-1029 | B31: 45460 | C31: South | D31: Eduardo | E31: Widget A | F31: Discount | G31: 15 | I31: =G31*H31 | J31: FALSE
A32: ORD-1169 | B32: 45381 | C32: West | D32: Eduardo | E32: Widget A | F32: Standard | G32: 4 | H32: 5.58 | I32: =G32*H32 | J32: FALSE
A33: ORD-1048 | B33: 45622 | C33: Central | D33: Ana | E33: Widget A | F33: Discount | H33: 7.89 | I33: =G33*H33 | J33: FALSE
A34: ORD-1064 | B34: 45502 | C34: West | D34: Daniela | E34: Widget A | F34: Premium | I34: =G34*H34
A35: ORD-1179 | B35: 45610 | C35: South | D35: Ana | E35: Gadget A | F35: Standard | H35: 111.42 | I35: =G35*H35
A36: ORD-1103 | B36: 45396 | C36: North | D36: Ana | E36: Gadget A | F36: Discount | G36: 1 | I36: =G36*H36 | J36: TRUE
A37: ORD-1152 | B37: 45477 | C37: North | D37: Bruno | E37: Widget B | F37: Premium | G37: 7 | I37: =G37*H37
A38: ORD-1028 | B38: 45622 | C38: South | D38: Ana | E38: Gadget A | F38: Standard | G38: 10 | H38: 87.54 | I38: =G38*H38 | J38: FALSE
A39: ORD-1012 | B39: 45417 | C39: South | D39: Carlos | E39: Gadget A | F39: Discount | I39: =G39*H39 | J39: TRUE
A40: ORD-1160 | B40: 45299 | C40: Central | D40: Daniela | E40: Widget C | F40: Standard | I40: =G40*H40 | J40: FALSE
...

Sheet Table_7
A1: OrderID | B1: Date | C1: Region | D1: Seller | E1: Product | F1: Category | G1: Units | H1: UnitPrice | I1: Revenue | J1: Approved
A2: ORD-1185 | B2: 45484 | C2: Central | D2: Carlos | E2: Widget B | F2: Standard | G2: 10 | H2: 68.15 | I2: =G2*H2
A3: ORD-1139 | B3: 45524 | C3: Central | D3: Carlos | E3: Gadget A | F3: Discount | G3: 13 | I3: =G3*H3
A4: ORD-1178 | B4: 45481 | C4: East | D4: Daniela | E4: Gadget B | F4: Discount | G4: 7 | H4: 73.58 | I4: =G4*H4
A5: ORD-1179 | B5: 45370 | C5: Central | D5: Fernanda | E5: Gadget B | F5: Discount | G5: 6 | I5: =G5*H5
A6: ORD-1103 | B6: 45581 | C6: West | D6: Fernanda | E6: Widget C | F6: Standard | G6: 14 | H6: 83.85 | I6: =G6*H6 | J6: FALSE
A7: ORD-1196 | B7: 45586 | C7: East | D7: Fernanda | E7: Widget B | F7: Premium | H7: 98.81 | I7: =G7*H7 | J7: FALSE
A8: ORD-1101 | B8: 45311 | C8: East | D8: Bruno | E8: Gadget B | F8: Premium | G8: 15 | I8: =G8*H8 | J8: FALSE
A9: ORD-1086 | B9: 45333 | C9: East | D9: Carlos | E9: Widget C | F9: Premium | G9: 4 | I9: =G9*H9 | J9: FALSE
A10: ORD-1113 | B10: 45453 | C10: East | D10: Eduardo | E10: Widget A | F10: Premium | G10: 12 | H10: 12.27 | I10: =G10*H10 | J10: FALSE
A11: ORD-1078 | B11: 45461 | C11: Central | D11: Carlos | E11: Widget A | F11: Standard | I11: =G11*H11 | J11: TRUE
A12: ORD-1167 | B12: 45330 | C12: East | D12: Fernanda | E12: Widget B | F12: Standard | G12: 1 | I12: =G12*H12 | J12: TRUE
A13: ORD-1137 | B13: 45382 | C13: North | D13: Daniela | E13: Widget A | F13: Discount | G13: 3 | H13: 111.73 | I13: =G13*H13 | J13: FALSE
A14: ORD-1020 | B14: 45595 | C14: West | D14: Fernanda | E14: Widget B | F14: Standard | H14: 11.72 | I14: =G14*H14 | J14: TRUE
A15: ORD-1170 | B15: 45483 | C15: West | D15: Ana | E15: Gadget A | F15: Standard | G15: 13 | I15: =G15*H15 | J15: FALSE
A16: ORD-1109 | B16: 45486 | C16: West | D16: Bruno | E16: Gadget B | F16: Premium | H16: 75.73 | I16: =G16*H16 | J16: FALSE
A17: ORD-1096 | B17: 45330 | C17: West | D17: Daniela | E17: Gadget B | F17: Standard | G17: 3 | I17: =G17*H17 | J17: FALSE
A18: ORD-1113 | B18: 45497 | C18: South | D18: Fernanda | E18: Widget C | F18: Premium | G18: 3 | H18: 64.01 | I18: =G18*H18 | J18: FALSE
A19: ORD-1012 | B19: 45500 | C19: Central | D19: Eduardo | E19: Gadget B | F19: Premium | H19: 18.31 | I19: =G19*H19
A20: ORD-1044 | B20: 45384 | C20: North | D20: Daniela | E20: Gadget B | F20: Premium | G20: 6 | H20: 66.34 | I20: =G20*H20
A21: ORD-1058 | B21: 45566 | C21: South | D21: Ana | E21: Gadget A | F21: Standard | I21: =G21*H21
A22: ORD-1167 | B22: 45349 | C22: North | D22: Fernanda | E22: Widget A | F22: Standard | G22: 12 | I22: =G22*H22
A23: ORD-1118 | B23: 45625 | C23: West | D23: Daniela | E23: Widget B | F23: Standard | I23: =G23*H23 | J23: FALSE
A24: ORD-1017 | B24: 45485 | C24: West | D24: Carlos | E24: Gadget B | F24: Premium | G24: 13 | H24: 92.73 | I24: =G24*H24 | J24: FALSE
A25: ORD-1065 | B25: 45615 | C25: Central | D25: Ana | E25: Widget A | F25: Standard | H25: 11.14 | I25: =G25*H25 | J25: FALSE
A26: ORD-1164 | B26: 45593 | C26: West | D26: Eduardo | E26: Gadget B | F26: Premium | G26: 15 | H26: 52.09 | I26: =G26*H26
A27: ORD-1103 | B27: 45451 | C27: East | D27: Ana | E27: Widget A | F27: Premium | G27: 10 | H27: 99.72 | I27: =G27*H27
A28: ORD-1165 | B28: 45293 | C28: East | D28: Eduardo | E28: Widget B | F28: Standard | I28: =G28*H28 | J28: TRUE
A29: ORD-1065 | B29: 45438 | C29: West | D29: Carlos | E29: Widget A | F29: Premium | H29: 84.98 | I29: =G29*H29 | J29: TRUE
A30: ORD-1148 | B30: 45482 | C30: Central | D30: Ana | E30: Gadget B | F30: Standard | G30: 9 | I30: =G30*H30 | J30: FALSE
A31: ORD-1069 | B31: 45441 | C31: East | D31: Bruno | E31: Widget A | F31: Premium | G31: 8 | H31: 14.51 | I31: =G31*H31 | J31: TRUE
A32: ORD-1004 | B32: 45305 | C32: South | D32: Fernanda | E32: Widget A | F32: Standard | G32: 5 | I32: =G32*H32
A33: ORD-1085 | B33: 45627 | C33: West | D33: Carlos | E33: Widget A | F33: Premium | G33: 9 | I33: =G33*H33
A34: ORD-1104 | B34: 45391 | C34: West | D34: Daniela | E34: Widget B | F34: Premium | G34: 1 | H34: 77.07 | I34: =G34*H34 | J34: FALSE
A35: ORD-1180 | B35: 45315 | C35: Central | D35: Fernanda | E35: Widget C | F35: Standard | G35: 8 | H35: 85.47 | I35: =G35*H35 | J35: TRUE
A36: ORD-1090 | B36: 45437 | C36: South | D36: Bruno | E36: Gadget A | F36: Standard | H36: 64.64 | I36: =G36*H36 | J36: FALSE
A37: ORD-1008 | B37: 45441 | C37: North | D37: Carlos | E37: Widget A | F37: Discount | G37: 11 | H37: 82.65 | I37: =G37*H37
A38: ORD-1078 | B38: 45450 | C38: North | D38: Ana | E38: Widget B | F38: Standard | G38: 14 | H38: 100.87 | I38: =G38*H38
A39: ORD-1075 | B39: 45374 | C39: North | D39: Ana | E39: Gadget B | F39: Premium | G39: 1 | I39: =G39*H39
A40: ORD-1115 | B40: 45459 | C40: Central | D40: Ana | E40: Widget B | F40: Premium | G40: 7 | H40: 35.92 | I40: =G40*H40 | J40: TRUE
...

Sheet Table_8
A1: OrderID | B1: Date | C1: Region | D1: Seller | E1: Product | F1: Category | G1: Units | H1: UnitPrice | I1: Revenue | J1: Approved
A2: ORD-1107 | B2: 45467 | C2: South | D2: Ana | E2: Widget B | F2: Discount | I2: =G2*H2 | J2: TRUE
A3: ORD-1085 | B3: 45510 | C3: West | D3: Eduardo | E3: Gadget A | F3: Standard | G3: 10 | I3: =G3*H3 | J3: FALSE
A4: ORD-1081 | B4: 45327 | C4: North | D4: Eduardo | E4: Widget C | F4: Premium | G4: 6 | I4: =G4*H4 | J4: TRUE
A5: ORD-1163 | B5: 45317 | C5: Central | D5: Daniela | E5: Widget A | F5: Discount | G5: 13 | I5: =G5*H5
A6: ORD-1169 | B6: 45574 | C6: Central | D6: Ana | E6: Gadget A | F6: Standard | G6: 15 | H6: 76.57 | I6: =G6*H6 | J6: TRUE
A7: ORD-1079 | B7: 45493 | C7: Central | D7: Carlos | E7: Widget C | F7: Discount | G7: 3 | H7: 109.6 | I7: =G7*H7
A8: ORD-1196 | B8: 45615 | C8: North | D8: Carlos | E8: Widget B | F8: Standard | G8: 11 | I8: =G8*H8 | J8: TRUE
A9: ORD-1055 | B9: 45322 | C9: South | D9: Fernanda | E9: Widget A | F9: Premium | G9: 4 | I9: =G9*H9
A10: ORD-1006 | B10: 45329 | C10: East | D10: Daniela | E10: Gadget A | F10: Standard | G10: 15 | H10: 91.23 | I10: =G10*H10 | J10: TRUE
A11: ORD-1026 | B11: 45616 | C11: North | D11: Carlos | E11: Widget B | F11: Discount | G11: 13 | I11: =G11*H11 | J11: TRUE
A12: ORD-1117 | B12: 45458 | C12: South | D12: Eduardo | E12: Gadget A | F12: Premium | G12: 2 | I12: =G12*H12 | J12: FALSE
A13: ORD-1065 | B13: 45298 | C13: South | D13: Eduardo | E13: Widget B | F13: Premium | G13: 2 | H13: 88.69 | I13: =G13*H13
A14: ORD-1164 | B14: 45313 | C14: East | D14: Daniela | E14: Widget B | F14: Premium | I14: =G14*H14 | J14: TRUE
A15: ORD-1195 | B15: 45455 | C15: South | D15: Ana | E15: Widget A | F15: Standard | I15: =G15*H15 | J15: TRUE
A16: ORD-1198 | B16: 45622 | C16: Central | D16: Fernanda | E16: Widget B | F16: Discount | I16: =G16*H16 | J16: FALSE
A17: ORD-1014 | B17: 45396 | C17: East | D17: Ana | E17: Widget A | F17: Discount | H17: 108.66 | I17: =G17*H17
A18: ORD-1030 | B18: 45436 | C18: Central | D18: Eduardo | E18: Widget B | F18: Premium | H18: 60.75 | I18: =G18*H18
A19: ORD-1067 | B19: 45564 | C19: South | D19: Daniela | E19: Gadget A | F19: Standard | G19: 7 | H19: 100.27 | I19: =G19*H19 | J19: FALSE
A20: ORD-1001 | B20: 45464 | C20: West | D20: Fernanda | E20: Widget A | F20: Standard | G20: 3 | I20: =G20*H20 | J20: TRUE
A21: ORD-1091 | B21: 45599 | C21: West | D21: Eduardo | E21: Gadget A | F21: Discount | G21: 6 | H21: 86.12 | I21: =G21*H21 | J21: TRUE
A22: ORD-1035 | B22: 45469 | C22: North | D22: Fernanda | E22: Widget A | F22: Standard | G22: 8 | I22: =G22*H22 | J22: FALSE
A23: ORD-1116 | B23: 45525 | C23: Central | D23: Ana | E23: Gadget B | F23: Discount | G23: 12 | I23: =G23*H23 | J23: TRUE
A24: ORD-1165 | B24: 45353 | C24: West | D24: Eduardo | E24: Widget C | F24: Discount | G24: 9 | I24: =G24*H24
A25: ORD-1037 | B25: 45300 | C25: West | D25: Carlos | E25: Gadget A | F25: Discount | G25: 6 | I25: =G25*H25
A26: ORD-1040 | B26: 45584 | C26: South | D26: Eduardo | E26: Gadget A | F26: Premium | H26: 91.8 | I26: =G26*H26
A27: ORD-1026 | B27: 45501 | C27: East | D27: Fernanda | E27: Gadget B | F27: Premium | H27: 27.52 | I27: =G27*H27 | J27: TRUE
A28: ORD-1018 | B28: 45414 | C28: West | D28: Carlos | E28: Widget C | F28: Discount | G28: 8 | I28: =G28*H28 | J28: FALSE
A29: ORD-1068 | B29: 45504 | C29: West | D29: Carlos | E29: Widget A | F29: Standard | I29: =G29*H29 | J29: TRUE
A30: ORD-1131 | B30: 45461 | C30: West | D30: Ana | E30: Widget B | F30: Premium | G30: 9 | H30: 76.54 | I30: =G30*H30 | J30: FALSE
A31: ORD-1159 | B31: 45523 | C31: North | D31: Ana | E31: Widget B | F31: Premium | I31: =G31*H31 | J31: TRUE
A32: ORD-1193 | B32: 45643 | C32: North | D32: Ana | E32: Widget B | F32: Standard | H32: 118.32 | I32: =G32*H32 | J32: TRUE
A33: ORD-1002 | B33: 45387 | C33: East | D33: Bruno | E33: Widget C | F33: Standard | I33: =G33*H33 | J33: TRUE
A34: ORD-1051 | B34: 45367 | C34: West | D34: Ana | E34: Widget A | F34: Standard | G34: 8 | I34: =G34*H34 | J34: FALSE
A35: ORD-1140 | B35: 45611 | C35: West | D35: Carlos | E35: Widget C | F35: Standard | H35: 96.57 | I35: =G35*H35 | J35: FALSE
A36: ORD-1165 | B36: 45614 | C36: North | D36: Ana | E36: Widget C | F36: Premium | H36: 99.07 | I36: =G36*H36 | J36: TRUE
A37: ORD-1045 | B37: 45457 | C37: East | D37: Carlos | E37: Gadget A | F37: Discount | I37: =G37*H37 | J37: TRUE
A38: ORD-1103 | B38: 45509 | C38: East | D38: Eduardo | E38: Gadget A | F38: Standard | H38: 77.18 | I38: =G38*H38 | J38: FALSE
A39: ORD-1172 | B39: 45510 | C39: North | D39: Fernanda | E39: Widget B | F39: Standard | G39: 5 | H39: 52.91 | I39: =G39*H39 | J39: TRUE
A40: ORD-1165 | B40: 45566 | C40: West | D40: Eduardo | E40: Gadget B | F40: Standard | I40: =G40*H40 | J40: TRUE
...

Sheet Table_9
A1: OrderID | B1: Date | C1: Region | D1: Seller | E1: Product | F1: Category | G1: Units | H1: UnitPrice | I1: Revenue | J1: Approved
A2: ORD-1027 | B2: 45375 | C2: East | D2: Fernanda | E2: Widget C | F2: Standard | G2: 14 | I2: =G2*H2 | J2: FALSE
A3: ORD-1013 | B3: 45565 | C3: South | D3: Bruno | E3: Widget A | F3: Premium | G3: 5 | H3: 114.81 | I3: =G3*H3 | J3: FALSE
A4: ORD-1011 | B4: 45586 | C4: East | D4: Bruno | E4: Gadget A | F4: Premium | H4: 10.34 | I4: =G4*H4 | J4: FALSE
A5: ORD-1026 | B5: 45595 | C5: East | D5: Ana | E5: Widget B | F5: Standard | I5: =G5*H5
A6: ORD-1198 | B6: 45546 | C6: South | D6: Eduardo | E6: Widget B | F6: Premium | I6: =G6*H6 | J6: FALSE
A7: ORD-1186 | B7: 45553 | C7: South | D7: Carlos | E7: Widget C | F7: Standard | I7: =G7*H7
A8: ORD-1046 | B8: 45366 | C8: North | D8: Fernanda | E8: Widget A | F8: Standard | G8: 1 | I8: =G8*H8 | J8: TRUE
A9: ORD-1067 | B9: 45316 | C9: Central | D9: Ana | E9: Widget B | F9: Discount | G9: 11 | H9: 71.55 | I9: =G9*H9 | J9: TRUE
A10: ORD-1000 | B10: 45454 | C10: South | D10: Carlos | E10: Widget C | F10: Standard | H10: 19.38 | I10: =G10*H10 | J10: FALSE
A11: ORD-1024 | B11: 45541 | C11: Central | D11: Ana | E11: Widget C | F11: Standard | G11: 10 | H11: 58.22 | I11: =G11*H11
A12: ORD-1197 | B12: 45525 | C12: North | D12: Bruno | E12: Gadget A | F12: Discount | G12: 1 | I12: =G12*H12
A13: ORD-1180 | B13: 45450 | C13: South | D13: Bruno | E13: Gadget B | F13: Standard | H13: 36.3 | I13: =G13*H13 | J13: TRUE
A14: ORD-1174 | B14: 45322 | C14: Central | D14: Ana | E14: Widget C | F14: Premium | H14: 43.18 | I14: =G14*H14 | J14: TRUE
A15: ORD-1158 | B15: 45461 | C15: North | D15: Ana | E15: Widget A | F15: Discount | H15: 93.19 | I15: =G15*H15 | J15: TRUE
A16: ORD-1087 | B16: 45596 | C16: North | D16: Daniela | E16: Widget C | F16: Discount | I16: =G16*H16 | J16: FALSE
A17: ORD-1180 | B17: 45426 | C17: South | D17: Bruno | E17: Widget B | F17: Discount | G17: 12 | H17: 95.85 | I17: =G17*H17 | J17: TRUE
A18: ORD-1084 | B18: 45440 | C18: East | D18: Bruno | E18: Gadget B | F18: Premium | G18: 5 | I18: =G18*H18
A19: ORD-1169 | B19: 45589 | C19: West | D19: Bruno | E19: Gadget A | F19: Standard | H19: 107.9 | I19: =G19*H19 | J19: TRUE
A20: ORD-1179 | B20: 45295 | C20: East | D20: Bruno | E20: Widget A | F20: Premium | G20: 4 | H20: 75.02 | I20: =G20*H20 | J20: FALSE
A21: ORD-1020 | B21: 45493 | C21: West | D21: Fernanda | E21: Widget A | F21: Standard | I21: =G21*H21 | J21: TRUE
A22: ORD-1200 | B22: 45474 | C22: South | D22: Carlos | E22: Widget A | F22: Standard | G22: 10 | I22: =G22*H22
A23: ORD-1105 | B23: 45426 | C23: East | D23: Bruno | E23: Widget C | F23: Discount | G23: 1 | H23: 106.29 | I23: =G23*H23 | J23: FALSE
A24: ORD-1015 | B24: 45407 | C24: West | D24: Bruno | E24: Widget C | F24: Discount | G24: 4 | H24: 65.28 | I24: =G24*H24 | J24: FALSE
A25: ORD-1152 | B25: 45625 | C25: East | D25: Carlos | E25: Gadget B | F25: Standard | H25: 93.23 | I25: =G25*H25 | J25: TRUE
A26: ORD-1093 | B26: 45626 | C26: East | D26: Carlos | E26: Gadget A | F26: Premium | G26: 12 | I26: =G26*H26
A27: ORD-1133 | B27: 45373 | C27: Central | D27: Bruno | E27: Widget C | F27: Premium | G27: 4 | I27: =G27*H27 | J27: TRUE
A28: ORD-1009 | B28: 45334 | C28: East | D28: Fernanda | E28: Widget C | F28: Premium | G28: 4 | I28: =G28*H28 | J28: TRUE
A29: ORD-1101 | B29: 45533 | C29: North | D29: Bruno | E29: Widget B | F29: Standard | I29: =G29*H29 | J29: FALSE
A30: ORD-1079 | B30: 45544 | C30: West | D30: Bruno | E30: Gadget A | F30: Premium | G30: 13 | H30: 37.46 | I30: =G30*H30 | J30: TRUE
A31: ORD-1108 | B31: 45541 | C31: North | D31: Ana | E31: Gadget A | F31: Standard | I31: =G31*H31
A32: ORD-1034 | B32: 45627 | C32: South | D32: Ana | E32: Gadget A | F32: Discount | I32: =G32*H32
A33: ORD-1009 | B33: 45473 | C33: South | D33: Daniela | E33: Widget C | F33: Premium | I33: =G33*H33 | J33: FALSE
A34: ORD-1018 | B34: 45537 | C34: South | D34: Daniela | E34: Gadget A | F34: Standard | I34: =G34*H34 | J34: TRUE
A35: ORD-1103 | B35: 45520 | C35: East | D35: Fernanda | E35: Widget A | F35: Premium | H35: 5.29 | I35: =G35*H35 | J35: FALSE
A36: ORD-1021 | B36: 45477 | C36: North | D36: Eduardo | E36: Gadget A | F36: Premium | I36: =G36*H36 | J36: FALSE
A37: ORD-1168 | B37: 45312 | C37: Central | D37: Ana | E37: Gadget B | F37: Standard | G37: 1 | I37: =G37*H37 | J37: FALSE
A38: ORD-1040 | B38: 45388 | C38: East | D38: Eduardo | E38: Widget A | F38: Discount | I38: =G38*H38 | J38: TRUE
A39: ORD-1012 | B39: 45435 | C39: North | D39: Fernanda | E39: Gadget A | F39: Premium | I39: =G39*H39 | J39: FALSE
A40: ORD-1090 | B40: 45337 | C40: West | D40: Carlos | E40: Widget B | F40: Standard | G40: 15 | I40: =G40*H40
...

Sheet Table_10
A1: OrderID | B1: Date | C1: Region | D1: Seller | E1: Product | F1: Category | G1: Units | H1: UnitPrice | I1: Revenue | J1: Approved
A2: ORD-1006 | B2: 45567 | C2: East | D2: Carlos | E2: Widget A | F2: Discount | G2: 11 | H2: 33.09 | I2: =G2*H2 | J2: FALSE
A3: ORD-1138 | B3: 45396 | C3: South | D3: Ana | E3: Gadget B | F3: Premium | G3: 5 | H3: 32.86 | I3: =G3*H3 | J3: FALSE
A4: ORD-1119 | B4: 45403 | C4: Central | D4: Daniela | E4: Gadget B | F4: Discount | G4: 5 | I4: =G4*H4 | J4: TRUE
A5: ORD-1081 | B5: 45564 | C5: East | D5: Daniela | E5: Widget C | F5: Discount | I5: =G5*H5
A6: ORD-1186 | B6: 45498 | C6: West | D6: Ana | E6: Widget C | F6: Premium | I6: =G6*H6 | J6: FALSE
A7: ORD-1018 | B7: 45391 | C7: West | D7: Fernanda | E7: Widget A | F7: Discount | G7: 6 | I7: =G7*H7 | J7: FALSE
A8: ORD-1151 | B8: 45611 | C8: East | D8: Bruno | E8: Widget A | F8: Standard | G8: 9 | I8: =G8*H8 | J8: TRUE
A9: ORD-1025 | B9: 45370 | C9: East | D9: Eduardo | E9: Widget C | F9: Discount | H9: 81.63 | I9: =G9*H9 | J9: FALSE
A10: ORD-1034 | B10: 45441 | C10: West | D10: Bruno | E10: Gadget B | F10: Discount | G10: 3 | H10: 74.14 | I10: =G10*H10 | J10: TRUE
A11: ORD-1083 | B11: 45475 | C11: Central | D11: Carlos | E11: Widget A | F11: Standard | I11: =G11*H11 | J11: TRUE
A12: ORD-1086 | B12: 45306 | C12: South | D12: Ana | E12: Widget A | F12: Premium | I12: =G12*H12
A13: ORD-1122 | B13: 45430 | C13: North | D13: Fernanda | E13: Gadget B | F13: Premium | I13: =G13*H13 | J13: TRUE
A14: ORD-1045 | B14: 45340 | C14: East | D14: Ana | E14: Gadget B | F14: Discount | G14: 8 | H14: 7.78 | I14: =G14*H14 | J14: FALSE
A15: ORD-1089 | B15: 45612 | C15: Central | D15: Daniela | E15: Gadget A | F15: Standard | H15: 91.3 | I15: =G15*H15 | J15: TRUE
A16: ORD-1105 | B16: 45515 | C16: North | D16: Ana | E16: Gadget A | F16: Premium | H16: 67.38 | I16: =G16*H16 | J16: TRUE
A17: ORD-1042 | B17: 45467 | C17: North | D17: Daniela | E17: Widget C | F17: Discount | H17: 41.74 | I17: =G17*H17 | J17: TRUE
A18: ORD-1195 | B18: 45403 | C18: West | D18: Daniela | E18: Gadget B | F18: Premium | I18: =G18*H18 | J18: TRUE
A19: ORD-1179 | B19: 45476 | C19: North | D19: Eduardo | E19: Widget A | F19: Discount | G19: 8 | H19: 71.68 | I19: =G19*H19 | J19: FALSE
A20: ORD-1022 | B20: 45351 | C20: North | D20: Fernanda | E20: Widget A | F20: Standard | H20: 38.41 | I20: =G20*H20
A21: ORD-1059 | B21: 45359 | C21: West | D21: Bruno | E21: Widget B | F21: Standard | H21: 89.6 | I21: =G21*H21
A22: ORD-1057 | B22: 45437 | C22: North | D22: Bruno | E22: Widget B | F22: Standard | H22: 55.87 | I22: =G22*H22 | J22: TRUE
A23: ORD-1170 | B23: 45642 | C23: North | D23: Fernanda | E23: Widget B | F23: Discount | G23: 14 | H23: 118.85 | I23: =G23*H23
A24: ORD-1053 | B24: 45474 | C24: Central | D24: Ana | E24: Widget A | F24: Premium | I24: =G24*H24 | J24: FALSE
A25: ORD-1026 | B25: 45616 | C25: East | D25: Carlos | E25: Gadget B | F25: Discount | H25: 113.69 | I25: =G25*H25 | J25: TRUE
A26: ORD-1025 | B26: 45411 | C26: West | D26: Ana | E26: Widget B | F26: Discount | H26: 115.23 | I26: =G26*H26
A27: ORD-1116 | B27: 45412 | C27: North | D27: Eduardo | E27: Widget B | F27: Standard | H27: 102.7 | I27: =G27*H27
A28: ORD-1183 | B28: 45326 | C28: West | D28: Fernanda | E28: Gadget A | F28: Standard | G28: 10 | H28: 81 | I28: =G28*H28 | J28: FALSE
A29: ORD-1017 | B29: 45636 | C29: East | D29: Daniela | E29: Widget A | F29: Discount | G29: 13 | H29: 73.2 | I29: =G29*H29 | J29: TRUE
A30: ORD-1040 | B30: 45356 | C30: North | D30: Daniela | E30: Gadget B | F30: Discount | I30: =G30*H30 | J30: TRUE
A31: ORD-1193 | B31: 45646 | C31: South | D31: Fernanda | E31: Gadget B | F31: Standard | G31: 8 | I31: =G31*H31 | J31: TRUE
A32: ORD-1026 | B32: 45555 | C32: South | D32: Daniela | E32: Gadget A | F32: Standard | I32: =G32*H32 | J32: FALSE
A33: ORD-1113 | B33: 45587 | C33: West | D33: Eduardo | E33: Gadget B | F33: Discount | G33: 8 | H33: 32.5 | I33: =G33*H33 | J33: FALSE
A34: ORD-1134 | B34: 45335 | C34: South | D34: Eduardo | E34: Widget A | F34: Premium | G34: 2 | I34: =G34*H34 | J34: TRUE
A35: ORD-1164 | B35: 45371 | C35: West | D35: Daniela | E35: Widget B | F35: Standard | G35: 4 | I35: =G35*H35 | J35: TRUE
A36: ORD-1083 | B36: 45404 | C36: North | D36: Daniela | E36: Widget B | F36: Premium | I36: =G36*H36 | J36: TRUE
A37: ORD-1126 | B37: 45458 | C37: East | D37: Ana | E37: Widget B | F37: Discount | H37: 64.34 | I37: =G37*H37 | J37: FALSE
A38: ORD-1133 | B38: 45434 | C38: East | D38: Ana | E38: Widget A | F38: Standard | I38: =G38*H38 | J38: TRUE
A39: ORD-1062 | B39: 45398 | C39: West | D39: Eduardo | E39: Gadget B | F39: Discount | H39: 91.07 | I39: =G39*H39 | J39: FALSE
A40: ORD-1088 | B40: 45312 | C40: North | D40: Ana | E40: Gadget A | F40: Standard | H40: 73.78 | I40: =G40*H40 | J40: FALSE
...

Sheet Table_11
A1: OrderID | B1: Date | C1: Region | D1: Seller | E1: Product | F1: Category | G1: Units | H1: UnitPrice | I1: Revenue | J1: Approved
A2: ORD-1006 | B2: 45323 | C2: South | D2: Daniela | E2: Widget C | F2: Discount | G2: 1 | H2: 58.15 | I2: =G2*H2 | J2: FALSE
A3: ORD-1014 | B3: 45431 | C3: West | D3: Bruno | E3: Gadget B | F3: Premium | I3: =G3*H3 | J3: TRUE
A4: ORD-1025 | B4: 45546 | C4: Central | D4: Fernanda | E4: Widget B | F4: Standard | H4: 24.05 | I4: =G4*H4
A5: ORD-1073 | B5: 45577 | C5: East | D5: Bruno | E5: Gadget A | F5: Discount | G5: 2 | H5: 50.79 | I5: =G5*H5 | J5: FALSE
A6: ORD-1054 | B6: 45507 | C6: East | D6: Ana | E6: Widget B | F6: Standard | G6: 5 | I6: =G6*H6 | J6: FALSE
A7: ORD-1141 | B7: 45427 | C7: East | D7: Eduardo | E7: Widget B | F7: Discount | H7: 94.34 | I7: =G7*H7 | J7: FALSE
A8: ORD-1113 | B8: 45589 | C8: West | D8: Bruno | E8: Widget C | F8: Standard | H8: 19.66 | I8: =G8*H8 | J8: TRUE
A9: ORD-1178 | B9: 45334 | C9: South | D9: Bruno | E9: Gadget B | F9: Premium | H9: 89.4 | I9: =G9*H9 | J9: TRUE
A10: ORD-1178 | B10: 45451 | C10: West | D10: Carlos | E10: Gadget A | F10: Discount | I10: =G10*H10 | J10: FALSE
A11: ORD-1073 | B11: 45372 | C11: South | D11: Daniela | E11: Widget C | F11: Standard | I11: =G11*H11 | J11: TRUE
A12: ORD-1091 | B12: 45521 | C12: South | D12: Fernanda | E12: Gadget A | F12: Discount | H12: 39.61 | I12: =G12*H12 | J12: TRUE
A13: ORD-1153 | B13: 45387 | C13: East | D13: Carlos | E13: Gadget A | F13: Standard | G13: 10 | H13: 60.36 | I13: =G13*H13 | J13: FALSE
A14: ORD-1188 | B14: 45476 | C14: West | D14: Carlos | E14: Gadget A | F14: Standard | I14: =G14*H14 | J14: FALSE
A15: ORD-1108 | B15: 45413 | C15: Central | D15: Ana | E15: Gadget A | F15: Premium | H15: 86.8 | I15: =G15*H15 | J15: FALSE
A16: ORD-1154 | B16: 45552 | C16: Central | D16: Daniela | E16: Gadget A | F16: Premium | I16: =G16*H16 | J16: TRUE
A17: ORD-1067 | B17: 45463 | C17: East | D17: Eduardo | E17: Gadget B | F17: Standard | H17: 109.1 | I17: =G17*H17
A18: ORD-1067 | B18: 45450 | C18: South | D18: Ana | E18: Gadget A | F18: Standard | H18: 69.95 | I18: =G18*H18 | J18: FALSE
A19: ORD-1011 | B19: 45606 | C19: South | D19: Bruno | E19: Widget B | F19: Premium | I19: =G19*H19 | J19: FALSE
A20: ORD-1166 | B20: 45431 | C20: East | D20: Bruno | E20: Gadget A | F20: Standard | G20: 12 | H20: 48.18 | I20: =G20*H20 | J20: FALSE
A21: ORD-1136 | B21: 45434 | C21: South | D21: Daniela | E21: Widget B | F21: Discount | I21: =G21*H21 | J21: FALSE
A22: ORD-1121 | B22: 45620 | C22: North | D22: Bruno | E22: Gadget A | F22: Standard | G22: 6 | H22: 109.85 | I22: =G22*H22 | J22: TRUE
A23: ORD-1037 | B23: 45547 | C23: South | D23: Eduardo | E23: Widget C | F23: Discount | G23: 12 | H23: 24.13 | I23: =G23*H23 | J23: FALSE
A24: ORD-1159 | B24: 45439 | C24: North | D24: Daniela | E24: Gadget B | F24: Premium | G24: 1 | H24: 107.48 | I24: =G24*H24
A25: ORD-1148 | B25: 45514 | C25: South | D25: Fernanda | E25: Gadget B | F25: Standard | I25: =G25*H25
A26: ORD-1118 | B26: 45621 | C26: South | D26: Eduardo | E26: Gadget A | F26: Premium | G26: 4 | H26: 60.6 | I26: =G26*H26 | J26: TRUE
A27: ORD-1046 | B27: 45437 | C27: Central | D27: Bruno | E27: Widget B | F27: Premium | H27: 72.29 | I27: =G27*H27 | J27: FALSE
A28: ORD-1005 | B28: 45318 | C28: East | D28: Carlos | E28: Widget A | F28: Standard | G28: 3 | I28: =G28*H28 | J28: FALSE
A29: ORD-1036 | B29: 45328 | C29: South | D29: Ana | E29: Gadget B | F29: Discount | H29: 73.51 | I29: =G29*H29 | J29: TRUE
A30: ORD-1095 | B30: 45604 | C30: North | D30: Carlos | E30: Widget B | F30: Premium | H30: 52.8 | I30: =G30*H30
A31: ORD-1143 | B31: 45378 | C31: South | D31: Ana | E31: Gadget A | F31: Premium | H31: 60.05 | I31: =G31*H31 | J31: FALSE
A32: ORD-1072 | B32: 45346 | C32: Central | D32: Bruno | E32: Widget C | F32: Standard | G32: 12 | H32: 11.6 | I32: =G32*H32 | J32: TRUE
A33: ORD-1044 | B33: 45519 | C33: Central | D33: Fernanda | E33: Widget A | F33: Standard | G33: 1 | H33: 99 | I33: =G33*H33
A34: ORD-1133 | B34: 45571 | C34: East | D34: Ana | E34: Widget C | F34: Standard | G34: 7 | H34: 96.1 | I34: =G34*H34 | J34: TRUE
A35: ORD-1020 | B35: 45425 | C35: South | D35: Daniela | E35: Widget C | F35: Discount | G35: 7 | I35: =G35*H35
A36: ORD-1083 | B36: 45409 | C36: South | D36: Fernanda | E36: Gadget A | F36: Premium | G36: 9 | H36: 101.69 | I36: =G36*H36
A37: ORD-1031 | B37: 45465 | C37: East | D37: Daniela | E37: Widget B | F37: Discount | G37: 3 | H37: 18.98 | I37: =G37*H37 | J37: TRUE
A38: ORD-1048 | B38: 45469 | C38: Central | D38: Fernanda | E38: Gadget A | F38: Discount | I38: =G38*H38
A39: ORD-1119 | B39: 45605 | C39: West | D39: Daniela | E39: Widget B | F39: Discount | G39: 9 | I39: =G39*H39 | J39: TRUE
A40: ORD-1026 | B40: 45534 | C40: Central | D40: Ana | E40: Widget B | F40: Standard | G40: 14 | H40: 72.24 | I40: =G40*H40
...

Sheet Table_12
A1: OrderID | B1: Date | C1: Region | D1: Seller | E1: Product | F1: Category | G1: Units | H1: UnitPrice | I1: Revenue | J1: Approved
A2: ORD-1126 | B2: 45562 | C2: Central | D2: Fernanda | E2: Widget A | F2: Premium | I2: =G2*H2 | J2: FALSE
A3: ORD-1048 | B3: 45553 | C3: North | D3: Ana | E3: Widget A | F3: Standard | G3: 10 | I3: =G3*H3 | J3: TRUE
A4: ORD-1058 | B4: 45378 | C4: East | D4: Carlos | E4: Gadget A | F4: Discount | H4: 67.48 | I4: =G4*H4 | J4: FALSE
A5: ORD-1100 | B5: 45410 | C5: Central | D5: Eduardo | E5: Gadget B | F5: Premium | G5: 13 | I5: =G5*H5 | J5: TRUE
A6: ORD-1074 | B6: 45616 | C6: East | D6: Fernanda | E6: Gadget B | F6: Premium | H6: 114.63 | I6: =G6*H6
A7: ORD-1059 | B7: 45463 | C7: West | D7: Carlos | E7: Widget C | F7: Discount | I7: =G7*H7 | J7: FALSE
A8: ORD-1134 | B8: 45537 | C8: North | D8: Daniela | E8: Widget B | F8: Premium | G8: 14 | I8: =G8*H8
A9: ORD-1195 | B9: 45634 | C9: Central | D9: Bruno | E9: Gadget A | F9: Discount | G9: 8 | H9: 46.24 | I9: =G9*H9 | J9: TRUE
A10: ORD-1144 | B10: 45372 | C10: East | D10: Ana | E10: Widget B | F10: Standard | I10: =G10*H10 | J10: TRUE
A11: ORD-1161 | B11: 45478 | C11: Central | D11: Carlos | E11: Widget C | F11: Standard | H11: 111.58 | I11: =G11*H11 | J11: TRUE
A12: ORD-1031 | B12: 45471 | C12: South | D12: Daniela | E12: Widget C | F12: Premium | G12: 14 | H12: 29.66 | I12: =G12*H12
A13: ORD-1084 | B13: 45332 | C13: Central | D13: Daniela | E13: Gadget A | F13: Premium | H13: 39.26 | I13: =G13*H13 | J13: FALSE
A14: ORD-1155 | B14: 45535 | C14: North | D14: Ana | E14: Gadget B | F14: Premium | I14: =G14*H14 | J14: TRUE
A15: ORD-1163 | B15: 45480 | C15: West | D15: Carlos | E15: Gadget A | F15: Standard | H15: 48.43 | I15: =G15*H15
A16: ORD-1044 | B16: 45383 | C16: South | D16: Eduardo | E16: Widget C | F16: Discount | H16: 109.71 | I16: =G16*H16 | J16: FALSE
A17: ORD-1030 | B17: 45585 | C17: South | D17: Daniela | E17: Gadget A | F17: Standard | G17: 4 | H17: 119.85 | I17: =G17*H17
A18: ORD-1009 | B18: 45316 | C18: West | D18: Eduardo | E18: Gadget A | F18: Discount | I18: =G18*H18
A19: ORD-1053 | B19: 45434 | C19: West | D19: Carlos | E19: Widget A | F19: Premium | I19: =G19*H19 | J19: TRUE
A20: ORD-1056 | B20: 45619 | C20: North | D20: Eduardo | E20: Widget B | F20: Premium | H20: 83.55 | I20: =G20*H20 | J20: TRUE
A21: ORD-1127 | B21: 45378 | C21: North | D21: Carlos | E21: Widget A | F21: Discount | H21: 5.02 | I21: =G21*H21 | J21: TRUE
A22: ORD-1074 | B22: 45538 | C22: South | D22: Eduardo | E22: Gadget B | F22: Standard | I22: =G22*H22 | J22: TRUE
A23: ORD-1187 | B23: 45492 | C23: Central | D23: Fernanda | E23: Widget C | F23: Standard | G23: 4 | H23: 115.08 | I23: =G23*H23 | J23: TRUE
A24: ORD-1167 | B24: 45614 | C24: Central | D24: Bruno | E24: Gadget A | F24: Premium | H24: 55.23 | I24: =G24*H24
A25: ORD-1073 | B25: 45528 | C25: West | D25: Ana | E25: Widget C | F25: Standard | I25: =G25*H25 | J25: TRUE
A26: ORD-1048 | B26: 45625 | C26: West | D26: Fernanda | E26: Widget B | F26: Discount | I26: =G26*H26 | J26: FALSE
A27: ORD-1079 | B27: 45484 | C27: Central | D27: Daniela | E27: Widget A | F27: Standard | G27: 4 | I27: =G27*H27
A28: ORD-1101 | B28: 45601 | C28: Central | D28: Daniela | E28: Widget A | F28: Premium | G28: 13 | I28: =G28*H28 | J28: TRUE
A29: ORD-1135 | B29: 45528 | C29: East | D29: Eduardo | E29: Widget A | F29: Standard | H29: 45.64 | I29: =G29*H29
A30: ORD-1059 | B30: 45369 | C30: East | D30: Bruno | E30: Widget B | F30: Standard | G30: 6 | H30: 79.47 | I30: =G30*H30 | J30: TRUE
A31: ORD-1120 | B31: 45651 | C31: Central | D31: Daniela | E31: Gadget A | F31: Standard | I31: =G31*H31 | J31: FALSE
A32: ORD-1191 | B32: 45462 | C32: South | D32: Fernanda | E32: Widget B | F32: Discount | G32: 11 | I32: =G32*H32 | J32: TRUE
A33: ORD-1011 | B33: 45450 | C33: South | D33: Fernanda | E33: Widget B | F33: Discount | G33: 6 | I33: =G33*H33 | J33: TRUE
A34: ORD-1029 | B34: 45492 | C34: Central | D34: Eduardo | E34: Widget B | F34: Premium | G34: 6 | H34: 65.94 | I34: =G34*H34 | J34: FALSE
A35: ORD-1083 | B35: 45400 | C35: East | D35: Eduardo | E35: Widget B | F35: Standard | I35: =G35*H35 | J35: FALSE
A36: ORD-1058 | B36: 45345 | C36: East | D36: Fernanda | E36: Widget B | F36: Premium | G36: 7 | H36: 36.08 | I36: =G36*H36 | J36: FALSE
A37: ORD-1079 | B37: 45553 | C37: Central | D37: Daniela | E37: Gadget A | F37: Premium | I37: =G37*H37 | J37: FALSE
A38: ORD-1049 | B38: 45484 | C38: West | D38: Ana | E38: Gadget B | F38: Premium | G38: 6 | I38: =G38*H38
A39: ORD-1146 | B39: 45537 | C39: West | D39: Eduardo | E39: Widget B | F39: Standard | I39: =G39*H39 | J39: TRUE
A40: ORD-1134 | B40: 45508 | C40: West | D40: Fernanda | E40: Widget B | F40: Premium | G40: 5 | I40: =G40*H40
...

Sheet Summary
A1: Region | B1: Total Revenue (Table_1) | C1: Total Revenue (Table_2) | D1: Grand Total | F1: Units > 5 (Table_3)
A2: North | B2: =SUMIF(Table_1!C2:C201,A2,Table_1!I2:I201) | C2: =SUMIF(Table_2!C2:C201,A2,Table_2!I2:I201) | D2: =B2+C2 | F2: =SUMIF(Table_3!G2:G201,">5",Table_3!G2:G201)
A3: South | B3: =SUMIF(Table_1!C2:C201,A3,Table_1!I2:I201) | C3: =SUMIF(Table_2!C2:C201,A3,Table_2!I2:I201) | D3: =B3+C3
A4: East | B4: =SUMIF(Table_1!C2:C201,A4,Table_1!I2:I201) | C4: =SUMIF(Table_2!C2:C201,A4,Table_2!I2:I201) | D4: =B4+C4
A5: West | B5: =SUMIF(Table_1!C2:C201,A5,Table_1!I2:I201) | C5: =SUMIF(Table_2!C2:C201,A5,Table_2!I2:I201) | D5: =B5+C5
A6: Central | B6: =SUMIF(Table_1!C2:C201,A6,Table_1!I2:I201) | C6: =SUMIF(Table_2!C2:C201,A6,Table_2!I2:I201) | D6: =B6+C6

Sheet Pivot_Simulated
A1: Region | B1: Product | C1: Total Units | D1: Total Revenue
A2: North | B2: Widget A | C2: =SUMIFS(Table_4!G2:G201,Table_4!C2:C201,A2,Table_4!E2:E201,B2) | D2: =SUMIFS(Table_4!I2:I201,Table_4!C2:C201,A2,Table_4!E2:E201,B2)
A3: North | B3: Widget B | C3: =SUMIFS(Table_4!G2:G201,Table_4!C2:C201,A3,Table_4!E2:E201,B3) | D3: =SUMIFS(Table_4!I2:I201,Table_4!C2:C201,A3,Table_4!E2:E201,B3)
A4: North | B4: Widget C | C4: =SUMIFS(Table_4!G2:G201,Table_4!C2:C201,A4,Table_4!E2:E201,B4) | D4: =SUMIFS(Table_4!I2:I201,Table_4!C2:C201,A4,Table_4!E2:E201,B4)
A5: North | B5: Gadget A | C5: =SUMIFS(Table_4!G2:G201,Table_4!C2:C201,A5,Table_4!E2:E201,B5) | D5: =SUMIFS(Table_4!I2:I201,Table_4!C2:C201,A5,Table_4!E2:E201,B5)
A6: North | B6: Gadget B | C6: =SUMIFS(Table_4!G2:G201,Table_4!C2:C201,A6,Table_4!E2:E201,B6) | D6: =SUMIFS(Table_4!I2:I201,Table_4!C2:C201,A6,Table_4!E2:E201,B6)
A7: South | B7: Widget A | C7: =SUMIFS(Table_4!G2:G201,Table_4!C2:C201,A7,Table_4!E2:E201,B7) | D7: =SUMIFS(Table_4!I2:I201,Table_4!C2:C201,A7,Table_4!E2:E201,B7)
A8: South | B8: Widget B | C8: =SUMIFS(Table_4!G2:G201,Table_4!C2:C201,A8,Table_4!E2:E201,B8) | D8: =SUMIFS(Table_4!I2:I201,Table_4!C2:C201,A8,Table_4!E2:E201,B8)
A9: South | B9: Widget C | C9: =SUMIFS(Table_4!G2:G201,Table_4!C2:C201,A9,Table_4!E2:E201,B9) | D9: =SUMIFS(Table_4!I2:I201,Table_4!C2:C201,A9,Table_4!E2:E201,B9)
